{
 "cells": [
  {
   "cell_type": "markdown",
   "id": "88a73109",
   "metadata": {},
   "source": [
    "`pip install pydantic`\n",
    "\n",
    "fastApi 설치 시 자동으로 함께 설치됩니다."
   ]
  },
  {
   "cell_type": "code",
   "execution_count": 3,
   "id": "aa378523",
   "metadata": {},
   "outputs": [],
   "source": [
    "from pydantic import BaseModel\n",
    "\n",
    "class User(BaseModel):\n",
    "    id: int\n",
    "    name: str\n",
    "    age: int\n",
    "    is_active: bool = True   # 기본값 설정"
   ]
  },
  {
   "cell_type": "code",
   "execution_count": 8,
   "id": "e2b3015b",
   "metadata": {},
   "outputs": [
    {
     "data": {
      "text/plain": [
       "User(id=1234, name='홍길동', age=30, is_active=True)"
      ]
     },
     "execution_count": 8,
     "metadata": {},
     "output_type": "execute_result"
    }
   ],
   "source": [
    "# id 는 int 형이어야하는데, 문자열로 들어갔어도 정해진 타입으로 처리됨\n",
    "user1 = User(id='1234', name='홍길동', age=30)\n",
    "user1"
   ]
  },
  {
   "cell_type": "code",
   "execution_count": 12,
   "id": "04006fb4",
   "metadata": {},
   "outputs": [
    {
     "data": {
      "text/plain": [
       "'{\"id\":1234,\"name\":\"홍길동\",\"age\":30,\"is_active\":true}'"
      ]
     },
     "execution_count": 12,
     "metadata": {},
     "output_type": "execute_result"
    }
   ],
   "source": [
    "user1.model_dump_json() # json 함수가 > model_dump_json 함수로 변경됨"
   ]
  },
  {
   "cell_type": "code",
   "execution_count": 10,
   "id": "cd9fc18a",
   "metadata": {},
   "outputs": [
    {
     "ename": "ValidationError",
     "evalue": "1 validation error for User\nid\n  Input should be a valid integer, unable to parse string as an integer [type=int_parsing, input_value='홍길동', input_type=str]\n    For further information visit https://errors.pydantic.dev/2.11/v/int_parsing",
     "output_type": "error",
     "traceback": [
      "\u001b[31m---------------------------------------------------------------------------\u001b[39m",
      "\u001b[31mValidationError\u001b[39m                           Traceback (most recent call last)",
      "\u001b[36mCell\u001b[39m\u001b[36m \u001b[39m\u001b[32mIn[10]\u001b[39m\u001b[32m, line 2\u001b[39m\n\u001b[32m      1\u001b[39m \u001b[38;5;66;03m# 하지만 형 변환이 안되는 케이스는 에러가 난다\u001b[39;00m\n\u001b[32m----> \u001b[39m\u001b[32m2\u001b[39m user2 = \u001b[43mUser\u001b[49m\u001b[43m(\u001b[49m\u001b[38;5;28;43mid\u001b[39;49m\u001b[43m=\u001b[49m\u001b[33;43m'\u001b[39;49m\u001b[33;43m홍길동\u001b[39;49m\u001b[33;43m'\u001b[39;49m\u001b[43m,\u001b[49m\u001b[43m \u001b[49m\u001b[43mname\u001b[49m\u001b[43m=\u001b[49m\u001b[33;43m'\u001b[39;49m\u001b[33;43m1234\u001b[39;49m\u001b[33;43m'\u001b[39;49m\u001b[43m,\u001b[49m\u001b[43m \u001b[49m\u001b[43mage\u001b[49m\u001b[43m=\u001b[49m\u001b[32;43m30\u001b[39;49m\u001b[43m)\u001b[49m\n\u001b[32m      3\u001b[39m user2\n",
      "\u001b[36mFile \u001b[39m\u001b[32mc:\\Potenup\\DeepLearning-Study\\.venv\\Lib\\site-packages\\pydantic\\main.py:253\u001b[39m, in \u001b[36mBaseModel.__init__\u001b[39m\u001b[34m(self, **data)\u001b[39m\n\u001b[32m    251\u001b[39m \u001b[38;5;66;03m# `__tracebackhide__` tells pytest and some other tools to omit this function from tracebacks\u001b[39;00m\n\u001b[32m    252\u001b[39m __tracebackhide__ = \u001b[38;5;28;01mTrue\u001b[39;00m\n\u001b[32m--> \u001b[39m\u001b[32m253\u001b[39m validated_self = \u001b[38;5;28;43mself\u001b[39;49m\u001b[43m.\u001b[49m\u001b[43m__pydantic_validator__\u001b[49m\u001b[43m.\u001b[49m\u001b[43mvalidate_python\u001b[49m\u001b[43m(\u001b[49m\u001b[43mdata\u001b[49m\u001b[43m,\u001b[49m\u001b[43m \u001b[49m\u001b[43mself_instance\u001b[49m\u001b[43m=\u001b[49m\u001b[38;5;28;43mself\u001b[39;49m\u001b[43m)\u001b[49m\n\u001b[32m    254\u001b[39m \u001b[38;5;28;01mif\u001b[39;00m \u001b[38;5;28mself\u001b[39m \u001b[38;5;129;01mis\u001b[39;00m \u001b[38;5;129;01mnot\u001b[39;00m validated_self:\n\u001b[32m    255\u001b[39m     warnings.warn(\n\u001b[32m    256\u001b[39m         \u001b[33m'\u001b[39m\u001b[33mA custom validator is returning a value other than `self`.\u001b[39m\u001b[38;5;130;01m\\n\u001b[39;00m\u001b[33m'\u001b[39m\n\u001b[32m    257\u001b[39m         \u001b[33m\"\u001b[39m\u001b[33mReturning anything other than `self` from a top level model validator isn\u001b[39m\u001b[33m'\u001b[39m\u001b[33mt supported when validating via `__init__`.\u001b[39m\u001b[38;5;130;01m\\n\u001b[39;00m\u001b[33m\"\u001b[39m\n\u001b[32m    258\u001b[39m         \u001b[33m'\u001b[39m\u001b[33mSee the `model_validator` docs (https://docs.pydantic.dev/latest/concepts/validators/#model-validators) for more details.\u001b[39m\u001b[33m'\u001b[39m,\n\u001b[32m    259\u001b[39m         stacklevel=\u001b[32m2\u001b[39m,\n\u001b[32m    260\u001b[39m     )\n",
      "\u001b[31mValidationError\u001b[39m: 1 validation error for User\nid\n  Input should be a valid integer, unable to parse string as an integer [type=int_parsing, input_value='홍길동', input_type=str]\n    For further information visit https://errors.pydantic.dev/2.11/v/int_parsing"
     ]
    }
   ],
   "source": [
    "# 하지만 형 변환이 안되는 케이스는 에러가 난다\n",
    "user2 = User(id='홍길동', name='1234', age=30)\n",
    "user2"
   ]
  }
 ],
 "metadata": {
  "kernelspec": {
   "display_name": "DeepLearning-Study (3.11.13)",
   "language": "python",
   "name": "python3"
  },
  "language_info": {
   "codemirror_mode": {
    "name": "ipython",
    "version": 3
   },
   "file_extension": ".py",
   "mimetype": "text/x-python",
   "name": "python",
   "nbconvert_exporter": "python",
   "pygments_lexer": "ipython3",
   "version": "3.11.13"
  }
 },
 "nbformat": 4,
 "nbformat_minor": 5
}
